[2024-11-18T21:06:39.818+0500] {local_task_job_runner.py:123} INFO - ::group::Pre task execution logs
[2024-11-18T21:06:39.833+0500] {taskinstance.py:2613} INFO - Dependencies all met for dep_context=non-requeueable deps ti=<TaskInstance: count_a.create_files manual__2024-11-18T16:06:35.669942+00:00 [queued]>
[2024-11-18T21:06:39.842+0500] {taskinstance.py:2613} INFO - Dependencies all met for dep_context=requeueable deps ti=<TaskInstance: count_a.create_files manual__2024-11-18T16:06:35.669942+00:00 [queued]>
[2024-11-18T21:06:39.842+0500] {taskinstance.py:2866} INFO - Starting attempt 1 of 2
[2024-11-18T21:06:39.864+0500] {taskinstance.py:2889} INFO - Executing <Task(PythonOperator): create_files> on 2024-11-18 16:06:35.669942+00:00
[2024-11-18T21:06:39.869+0500] {standard_task_runner.py:72} INFO - Started process 21048 to run task
[2024-11-18T21:06:39.873+0500] {standard_task_runner.py:104} INFO - Running: ['airflow', 'tasks', 'run', 'count_a', 'create_files', 'manual__2024-11-18T16:06:35.669942+00:00', '--job-id', '6', '--raw', '--subdir', 'DAGS_FOLDER/dag_1.py', '--cfg-path', '/tmp/tmph08hky9s']
[2024-11-18T21:06:39.874+0500] {standard_task_runner.py:105} INFO - Job 6: Subtask create_files
[2024-11-18T21:06:39.922+0500] {task_command.py:467} INFO - Running <TaskInstance: count_a.create_files manual__2024-11-18T16:06:35.669942+00:00 [running]> on host archlinux
[2024-11-18T21:06:40.025+0500] {taskinstance.py:3132} INFO - Exporting env vars: AIRFLOW_CTX_DAG_OWNER='airflow' AIRFLOW_CTX_DAG_ID='count_a' AIRFLOW_CTX_TASK_ID='create_files' AIRFLOW_CTX_EXECUTION_DATE='2024-11-18T16:06:35.669942+00:00' AIRFLOW_CTX_TRY_NUMBER='1' AIRFLOW_CTX_DAG_RUN_ID='manual__2024-11-18T16:06:35.669942+00:00'
[2024-11-18T21:06:40.027+0500] {logging_mixin.py:190} INFO - Task instance is in running state
[2024-11-18T21:06:40.030+0500] {logging_mixin.py:190} INFO -  Previous state of the Task instance: queued
[2024-11-18T21:06:40.031+0500] {logging_mixin.py:190} INFO - Current task name:create_files state:running start_date:2024-11-18 16:06:39.834360+00:00
[2024-11-18T21:06:40.031+0500] {logging_mixin.py:190} INFO - Dag name:count_a and current dag run status:running
[2024-11-18T21:06:40.031+0500] {taskinstance.py:731} INFO - ::endgroup::
[2024-11-18T21:06:40.032+0500] {taskinstance.py:3311} ERROR - Task failed with exception
Traceback (most recent call last):
  File "/home/AtlasRise/airflow/airflow_env/lib/python3.12/site-packages/airflow/models/taskinstance.py", line 767, in _execute_task
    result = _execute_callable(context=context, **execute_callable_kwargs)
             ^^^^^^^^^^^^^^^^^^^^^^^^^^^^^^^^^^^^^^^^^^^^^^^^^^^^^^^^^^^^^
  File "/home/AtlasRise/airflow/airflow_env/lib/python3.12/site-packages/airflow/models/taskinstance.py", line 733, in _execute_callable
    return ExecutionCallableRunner(
           ^^^^^^^^^^^^^^^^^^^^^^^^
  File "/home/AtlasRise/airflow/airflow_env/lib/python3.12/site-packages/airflow/utils/operator_helpers.py", line 252, in run
    return self.func(*args, **kwargs)
           ^^^^^^^^^^^^^^^^^^^^^^^^^^
  File "/home/AtlasRise/airflow/airflow_env/lib/python3.12/site-packages/airflow/models/baseoperator.py", line 417, in wrapper
    return func(self, *args, **kwargs)
           ^^^^^^^^^^^^^^^^^^^^^^^^^^^
  File "/home/AtlasRise/airflow/airflow_env/lib/python3.12/site-packages/airflow/operators/python.py", line 238, in execute
    return_value = self.execute_callable()
                   ^^^^^^^^^^^^^^^^^^^^^^^
  File "/home/AtlasRise/airflow/airflow_env/lib/python3.12/site-packages/airflow/operators/python.py", line 256, in execute_callable
    return runner.run(*self.op_args, **self.op_kwargs)
           ^^^^^^^^^^^^^^^^^^^^^^^^^^^^^^^^^^^^^^^^^^^
  File "/home/AtlasRise/airflow/airflow_env/lib/python3.12/site-packages/airflow/utils/operator_helpers.py", line 252, in run
    return self.func(*args, **kwargs)
           ^^^^^^^^^^^^^^^^^^^^^^^^^^
  File "/home/AtlasRise/airflow/dags/dag_1.py", line 25, in create_files
    with open(f'file_{i}.txt', 'w') as f:
         ^^^^^^^^^^^^^^^^^^^^^^^^^^
PermissionError: [Errno 13] Permission denied: 'file_0.txt'
[2024-11-18T21:06:40.059+0500] {logging_mixin.py:190} INFO - Task instance in failure state
[2024-11-18T21:06:40.060+0500] {logging_mixin.py:190} INFO - Task start:2024-11-18 16:06:39.834360+00:00 end:2024-11-18 16:06:40.058028+00:00 duration:0.223668
[2024-11-18T21:06:40.060+0500] {logging_mixin.py:190} INFO - Task:<Task(PythonOperator): create_files> dag:<DAG: count_a> dagrun:<DagRun count_a @ 2024-11-18 16:06:35.669942+00:00: manual__2024-11-18T16:06:35.669942+00:00, state:running, queued_at: 2024-11-18 16:06:35.701795+00:00. externally triggered: True>
[2024-11-18T21:06:40.060+0500] {logging_mixin.py:190} INFO - Failure caused by [Errno 13] Permission denied: 'file_0.txt'
[2024-11-18T21:06:40.061+0500] {taskinstance.py:1225} INFO - Marking task as UP_FOR_RETRY. dag_id=count_a, task_id=create_files, run_id=manual__2024-11-18T16:06:35.669942+00:00, execution_date=20241118T160635, start_date=20241118T160639, end_date=20241118T160640
[2024-11-18T21:06:40.084+0500] {taskinstance.py:340} INFO - ::group::Post task execution logs
[2024-11-18T21:06:40.084+0500] {standard_task_runner.py:124} ERROR - Failed to execute job 6 for task create_files ([Errno 13] Permission denied: 'file_0.txt'; 21048)
Traceback (most recent call last):
  File "/home/AtlasRise/airflow/airflow_env/lib/python3.12/site-packages/airflow/task/task_runner/standard_task_runner.py", line 117, in _start_by_fork
    ret = args.func(args, dag=self.dag)
          ^^^^^^^^^^^^^^^^^^^^^^^^^^^^^
  File "/home/AtlasRise/airflow/airflow_env/lib/python3.12/site-packages/airflow/cli/cli_config.py", line 49, in command
    return func(*args, **kwargs)
           ^^^^^^^^^^^^^^^^^^^^^
  File "/home/AtlasRise/airflow/airflow_env/lib/python3.12/site-packages/airflow/utils/cli.py", line 116, in wrapper
    return f(*args, **kwargs)
           ^^^^^^^^^^^^^^^^^^
  File "/home/AtlasRise/airflow/airflow_env/lib/python3.12/site-packages/airflow/cli/commands/task_command.py", line 483, in task_run
    task_return_code = _run_task_by_selected_method(args, _dag, ti)
                       ^^^^^^^^^^^^^^^^^^^^^^^^^^^^^^^^^^^^^^^^^^^^
  File "/home/AtlasRise/airflow/airflow_env/lib/python3.12/site-packages/airflow/cli/commands/task_command.py", line 256, in _run_task_by_selected_method
    return _run_raw_task(args, ti)
           ^^^^^^^^^^^^^^^^^^^^^^^
  File "/home/AtlasRise/airflow/airflow_env/lib/python3.12/site-packages/airflow/cli/commands/task_command.py", line 341, in _run_raw_task
    return ti._run_raw_task(
           ^^^^^^^^^^^^^^^^^
  File "/home/AtlasRise/airflow/airflow_env/lib/python3.12/site-packages/airflow/utils/session.py", line 97, in wrapper
    return func(*args, session=session, **kwargs)
           ^^^^^^^^^^^^^^^^^^^^^^^^^^^^^^^^^^^^^^
  File "/home/AtlasRise/airflow/airflow_env/lib/python3.12/site-packages/airflow/models/taskinstance.py", line 3005, in _run_raw_task
    return _run_raw_task(
           ^^^^^^^^^^^^^^
  File "/home/AtlasRise/airflow/airflow_env/lib/python3.12/site-packages/airflow/models/taskinstance.py", line 273, in _run_raw_task
    TaskInstance._execute_task_with_callbacks(
  File "/home/AtlasRise/airflow/airflow_env/lib/python3.12/site-packages/airflow/models/taskinstance.py", line 3159, in _execute_task_with_callbacks
    result = self._execute_task(context, task_orig)
             ^^^^^^^^^^^^^^^^^^^^^^^^^^^^^^^^^^^^^^
  File "/home/AtlasRise/airflow/airflow_env/lib/python3.12/site-packages/airflow/models/taskinstance.py", line 3183, in _execute_task
    return _execute_task(self, context, task_orig)
           ^^^^^^^^^^^^^^^^^^^^^^^^^^^^^^^^^^^^^^^
  File "/home/AtlasRise/airflow/airflow_env/lib/python3.12/site-packages/airflow/models/taskinstance.py", line 767, in _execute_task
    result = _execute_callable(context=context, **execute_callable_kwargs)
             ^^^^^^^^^^^^^^^^^^^^^^^^^^^^^^^^^^^^^^^^^^^^^^^^^^^^^^^^^^^^^
  File "/home/AtlasRise/airflow/airflow_env/lib/python3.12/site-packages/airflow/models/taskinstance.py", line 733, in _execute_callable
    return ExecutionCallableRunner(
           ^^^^^^^^^^^^^^^^^^^^^^^^
  File "/home/AtlasRise/airflow/airflow_env/lib/python3.12/site-packages/airflow/utils/operator_helpers.py", line 252, in run
    return self.func(*args, **kwargs)
           ^^^^^^^^^^^^^^^^^^^^^^^^^^
  File "/home/AtlasRise/airflow/airflow_env/lib/python3.12/site-packages/airflow/models/baseoperator.py", line 417, in wrapper
    return func(self, *args, **kwargs)
           ^^^^^^^^^^^^^^^^^^^^^^^^^^^
  File "/home/AtlasRise/airflow/airflow_env/lib/python3.12/site-packages/airflow/operators/python.py", line 238, in execute
    return_value = self.execute_callable()
                   ^^^^^^^^^^^^^^^^^^^^^^^
  File "/home/AtlasRise/airflow/airflow_env/lib/python3.12/site-packages/airflow/operators/python.py", line 256, in execute_callable
    return runner.run(*self.op_args, **self.op_kwargs)
           ^^^^^^^^^^^^^^^^^^^^^^^^^^^^^^^^^^^^^^^^^^^
  File "/home/AtlasRise/airflow/airflow_env/lib/python3.12/site-packages/airflow/utils/operator_helpers.py", line 252, in run
    return self.func(*args, **kwargs)
           ^^^^^^^^^^^^^^^^^^^^^^^^^^
  File "/home/AtlasRise/airflow/dags/dag_1.py", line 25, in create_files
    with open(f'file_{i}.txt', 'w') as f:
         ^^^^^^^^^^^^^^^^^^^^^^^^^^
PermissionError: [Errno 13] Permission denied: 'file_0.txt'
[2024-11-18T21:06:40.128+0500] {local_task_job_runner.py:266} INFO - Task exited with return code 1
[2024-11-18T21:06:40.164+0500] {taskinstance.py:3895} INFO - 0 downstream tasks scheduled from follow-on schedule check
[2024-11-18T21:06:40.166+0500] {local_task_job_runner.py:245} INFO - ::endgroup::
