[2024-11-18T21:10:38.312+0500] {local_task_job_runner.py:123} INFO - ::group::Pre task execution logs
[2024-11-18T21:10:38.327+0500] {taskinstance.py:2613} INFO - Dependencies all met for dep_context=non-requeueable deps ti=<TaskInstance: count_a.count_a manual__2024-11-18T16:10:29.434302+00:00 [queued]>
[2024-11-18T21:10:38.336+0500] {taskinstance.py:2613} INFO - Dependencies all met for dep_context=requeueable deps ti=<TaskInstance: count_a.count_a manual__2024-11-18T16:10:29.434302+00:00 [queued]>
[2024-11-18T21:10:38.336+0500] {taskinstance.py:2866} INFO - Starting attempt 1 of 2
[2024-11-18T21:10:38.357+0500] {taskinstance.py:2889} INFO - Executing <Task(PythonOperator): count_a> on 2024-11-18 16:10:29.434302+00:00
[2024-11-18T21:10:38.363+0500] {standard_task_runner.py:72} INFO - Started process 21343 to run task
[2024-11-18T21:10:38.367+0500] {standard_task_runner.py:104} INFO - Running: ['airflow', 'tasks', 'run', 'count_a', 'count_a', 'manual__2024-11-18T16:10:29.434302+00:00', '--job-id', '8', '--raw', '--subdir', 'DAGS_FOLDER/dag_1.py', '--cfg-path', '/tmp/tmpkmuf6z7m']
[2024-11-18T21:10:38.368+0500] {standard_task_runner.py:105} INFO - Job 8: Subtask count_a
[2024-11-18T21:10:38.417+0500] {task_command.py:467} INFO - Running <TaskInstance: count_a.count_a manual__2024-11-18T16:10:29.434302+00:00 [running]> on host archlinux
[2024-11-18T21:10:38.519+0500] {taskinstance.py:3132} INFO - Exporting env vars: AIRFLOW_CTX_DAG_OWNER='airflow' AIRFLOW_CTX_DAG_ID='count_a' AIRFLOW_CTX_TASK_ID='count_a' AIRFLOW_CTX_EXECUTION_DATE='2024-11-18T16:10:29.434302+00:00' AIRFLOW_CTX_TRY_NUMBER='1' AIRFLOW_CTX_DAG_RUN_ID='manual__2024-11-18T16:10:29.434302+00:00'
[2024-11-18T21:10:38.521+0500] {logging_mixin.py:190} INFO - Task instance is in running state
[2024-11-18T21:10:38.521+0500] {logging_mixin.py:190} INFO -  Previous state of the Task instance: queued
[2024-11-18T21:10:38.521+0500] {logging_mixin.py:190} INFO - Current task name:count_a state:running start_date:2024-11-18 16:10:38.327619+00:00
[2024-11-18T21:10:38.522+0500] {logging_mixin.py:190} INFO - Dag name:count_a and current dag run status:running
[2024-11-18T21:10:38.522+0500] {taskinstance.py:731} INFO - ::endgroup::
[2024-11-18T21:10:38.523+0500] {taskinstance.py:3311} ERROR - Task failed with exception
Traceback (most recent call last):
  File "/home/AtlasRise/airflow/airflow_env/lib/python3.12/site-packages/airflow/models/taskinstance.py", line 767, in _execute_task
    result = _execute_callable(context=context, **execute_callable_kwargs)
             ^^^^^^^^^^^^^^^^^^^^^^^^^^^^^^^^^^^^^^^^^^^^^^^^^^^^^^^^^^^^^
  File "/home/AtlasRise/airflow/airflow_env/lib/python3.12/site-packages/airflow/models/taskinstance.py", line 733, in _execute_callable
    return ExecutionCallableRunner(
           ^^^^^^^^^^^^^^^^^^^^^^^^
  File "/home/AtlasRise/airflow/airflow_env/lib/python3.12/site-packages/airflow/utils/operator_helpers.py", line 252, in run
    return self.func(*args, **kwargs)
           ^^^^^^^^^^^^^^^^^^^^^^^^^^
  File "/home/AtlasRise/airflow/airflow_env/lib/python3.12/site-packages/airflow/models/baseoperator.py", line 417, in wrapper
    return func(self, *args, **kwargs)
           ^^^^^^^^^^^^^^^^^^^^^^^^^^^
  File "/home/AtlasRise/airflow/airflow_env/lib/python3.12/site-packages/airflow/operators/python.py", line 238, in execute
    return_value = self.execute_callable()
                   ^^^^^^^^^^^^^^^^^^^^^^^
  File "/home/AtlasRise/airflow/airflow_env/lib/python3.12/site-packages/airflow/operators/python.py", line 256, in execute_callable
    return runner.run(*self.op_args, **self.op_kwargs)
           ^^^^^^^^^^^^^^^^^^^^^^^^^^^^^^^^^^^^^^^^^^^
  File "/home/AtlasRise/airflow/airflow_env/lib/python3.12/site-packages/airflow/utils/operator_helpers.py", line 252, in run
    return self.func(*args, **kwargs)
           ^^^^^^^^^^^^^^^^^^^^^^^^^^
  File "/home/AtlasRise/airflow/dags/dag_1.py", line 32, in count_a
    with open(f'file_{i}.txt', 'r') as f:
         ^^^^^^^^^^^^^^^^^^^^^^^^^^
FileNotFoundError: [Errno 2] No such file or directory: 'file_0.txt'
[2024-11-18T21:10:38.535+0500] {logging_mixin.py:190} INFO - Task instance in failure state
[2024-11-18T21:10:38.535+0500] {logging_mixin.py:190} INFO - Task start:2024-11-18 16:10:38.327619+00:00 end:2024-11-18 16:10:38.534384+00:00 duration:0.206765
[2024-11-18T21:10:38.536+0500] {logging_mixin.py:190} INFO - Task:<Task(PythonOperator): count_a> dag:<DAG: count_a> dagrun:<DagRun count_a @ 2024-11-18 16:10:29.434302+00:00: manual__2024-11-18T16:10:29.434302+00:00, state:running, queued_at: 2024-11-18 16:10:29.448471+00:00. externally triggered: True>
[2024-11-18T21:10:38.536+0500] {logging_mixin.py:190} INFO - Failure caused by [Errno 2] No such file or directory: 'file_0.txt'
[2024-11-18T21:10:38.536+0500] {taskinstance.py:1225} INFO - Marking task as UP_FOR_RETRY. dag_id=count_a, task_id=count_a, run_id=manual__2024-11-18T16:10:29.434302+00:00, execution_date=20241118T161029, start_date=20241118T161038, end_date=20241118T161038
[2024-11-18T21:10:38.556+0500] {taskinstance.py:340} INFO - ::group::Post task execution logs
[2024-11-18T21:10:38.556+0500] {standard_task_runner.py:124} ERROR - Failed to execute job 8 for task count_a ([Errno 2] No such file or directory: 'file_0.txt'; 21343)
Traceback (most recent call last):
  File "/home/AtlasRise/airflow/airflow_env/lib/python3.12/site-packages/airflow/task/task_runner/standard_task_runner.py", line 117, in _start_by_fork
    ret = args.func(args, dag=self.dag)
          ^^^^^^^^^^^^^^^^^^^^^^^^^^^^^
  File "/home/AtlasRise/airflow/airflow_env/lib/python3.12/site-packages/airflow/cli/cli_config.py", line 49, in command
    return func(*args, **kwargs)
           ^^^^^^^^^^^^^^^^^^^^^
  File "/home/AtlasRise/airflow/airflow_env/lib/python3.12/site-packages/airflow/utils/cli.py", line 116, in wrapper
    return f(*args, **kwargs)
           ^^^^^^^^^^^^^^^^^^
  File "/home/AtlasRise/airflow/airflow_env/lib/python3.12/site-packages/airflow/cli/commands/task_command.py", line 483, in task_run
    task_return_code = _run_task_by_selected_method(args, _dag, ti)
                       ^^^^^^^^^^^^^^^^^^^^^^^^^^^^^^^^^^^^^^^^^^^^
  File "/home/AtlasRise/airflow/airflow_env/lib/python3.12/site-packages/airflow/cli/commands/task_command.py", line 256, in _run_task_by_selected_method
    return _run_raw_task(args, ti)
           ^^^^^^^^^^^^^^^^^^^^^^^
  File "/home/AtlasRise/airflow/airflow_env/lib/python3.12/site-packages/airflow/cli/commands/task_command.py", line 341, in _run_raw_task
    return ti._run_raw_task(
           ^^^^^^^^^^^^^^^^^
  File "/home/AtlasRise/airflow/airflow_env/lib/python3.12/site-packages/airflow/utils/session.py", line 97, in wrapper
    return func(*args, session=session, **kwargs)
           ^^^^^^^^^^^^^^^^^^^^^^^^^^^^^^^^^^^^^^
  File "/home/AtlasRise/airflow/airflow_env/lib/python3.12/site-packages/airflow/models/taskinstance.py", line 3005, in _run_raw_task
    return _run_raw_task(
           ^^^^^^^^^^^^^^
  File "/home/AtlasRise/airflow/airflow_env/lib/python3.12/site-packages/airflow/models/taskinstance.py", line 273, in _run_raw_task
    TaskInstance._execute_task_with_callbacks(
  File "/home/AtlasRise/airflow/airflow_env/lib/python3.12/site-packages/airflow/models/taskinstance.py", line 3159, in _execute_task_with_callbacks
    result = self._execute_task(context, task_orig)
             ^^^^^^^^^^^^^^^^^^^^^^^^^^^^^^^^^^^^^^
  File "/home/AtlasRise/airflow/airflow_env/lib/python3.12/site-packages/airflow/models/taskinstance.py", line 3183, in _execute_task
    return _execute_task(self, context, task_orig)
           ^^^^^^^^^^^^^^^^^^^^^^^^^^^^^^^^^^^^^^^
  File "/home/AtlasRise/airflow/airflow_env/lib/python3.12/site-packages/airflow/models/taskinstance.py", line 767, in _execute_task
    result = _execute_callable(context=context, **execute_callable_kwargs)
             ^^^^^^^^^^^^^^^^^^^^^^^^^^^^^^^^^^^^^^^^^^^^^^^^^^^^^^^^^^^^^
  File "/home/AtlasRise/airflow/airflow_env/lib/python3.12/site-packages/airflow/models/taskinstance.py", line 733, in _execute_callable
    return ExecutionCallableRunner(
           ^^^^^^^^^^^^^^^^^^^^^^^^
  File "/home/AtlasRise/airflow/airflow_env/lib/python3.12/site-packages/airflow/utils/operator_helpers.py", line 252, in run
    return self.func(*args, **kwargs)
           ^^^^^^^^^^^^^^^^^^^^^^^^^^
  File "/home/AtlasRise/airflow/airflow_env/lib/python3.12/site-packages/airflow/models/baseoperator.py", line 417, in wrapper
    return func(self, *args, **kwargs)
           ^^^^^^^^^^^^^^^^^^^^^^^^^^^
  File "/home/AtlasRise/airflow/airflow_env/lib/python3.12/site-packages/airflow/operators/python.py", line 238, in execute
    return_value = self.execute_callable()
                   ^^^^^^^^^^^^^^^^^^^^^^^
  File "/home/AtlasRise/airflow/airflow_env/lib/python3.12/site-packages/airflow/operators/python.py", line 256, in execute_callable
    return runner.run(*self.op_args, **self.op_kwargs)
           ^^^^^^^^^^^^^^^^^^^^^^^^^^^^^^^^^^^^^^^^^^^
  File "/home/AtlasRise/airflow/airflow_env/lib/python3.12/site-packages/airflow/utils/operator_helpers.py", line 252, in run
    return self.func(*args, **kwargs)
           ^^^^^^^^^^^^^^^^^^^^^^^^^^
  File "/home/AtlasRise/airflow/dags/dag_1.py", line 32, in count_a
    with open(f'file_{i}.txt', 'r') as f:
         ^^^^^^^^^^^^^^^^^^^^^^^^^^
FileNotFoundError: [Errno 2] No such file or directory: 'file_0.txt'
[2024-11-18T21:10:38.588+0500] {local_task_job_runner.py:266} INFO - Task exited with return code 1
[2024-11-18T21:10:38.611+0500] {taskinstance.py:3895} INFO - 0 downstream tasks scheduled from follow-on schedule check
[2024-11-18T21:10:38.612+0500] {local_task_job_runner.py:245} INFO - ::endgroup::
